Workbook

Sheet Description
A25: Version Number | E25: 1.1
A26: Release Date | E26: Oc 2024
A27: GHG Alignments | E27: IPCC
E28: GHG Protocol
E29: Emep-EEA-Guidebook
E30: USEPA- Air Emission Factors
A31: Data includes | E31: Original database for CF for Chromite mining
A34: Created by | E34: Suvha Lama
A35: Check by

Sheet Processess
A1: No. | B1: Process_code | C1: Process_desc | D1: Scope
A2: 1 | B2: DG_CONS_EM | C2: CO2 Emission from burning of diesel fuels in Diesel Generators | D2: Scope_1
A3: 2 | B3: LPG_CONS_EM | C3: CO2 Emission from burning of LPG Fuel | D3: Scope_1
A4: 3 | B4: COMP_EM | C4: CO2 Emission from composting of organic waste | D4: Scope_1
A5: 4 | B5: BLAST_EM | C5: CO2 Emission from use of explosives | D5: Scope_1 | E5: No emission Factor
A6: 5 | B6: OVER_B_EM | C6: CO2 Emission from anaerobic digestion of overburden | D6: Scope_1
A7: 6 | B7: HEMV_FUEL_EM | C7: CO2 Emission from burning of diesel fuel in Heavy Earth Moving Vehicle | D7: Scope_1
A8: 7 | B8: LMV_EM_D | C8: CO2 Emission from burning of petrol fuel in Light Motor Vehicle | D8: Scope_1
A9: 8 | B9: LMV_EM_G | C9: CO2 Emission from burning of diesel fuel in Light Motor Vehicle | D9: Scope_1
A10: 9 | B10: PUMP_DEW_EM | C10: CO2 Emission from burning of diesel for pumping of water | D10: Scope_1
A11: 10 | B11: PORT_DG_EM | C11: CO2 Emission from burning of diesel fuels in Portable Diesel Generators | D11: Scope_1
A12: 11 | B12: AC_EM | C12: CO2 Emission from Leakages of Refrigants | D12: Scope_1
A13: 12 | B13: OXY_ACE_EM | C13: CO2 Emission from burning oxy-acetylene cylinder for wielding | D13: Scope_1
A14: 13 | B14: DIESEL_DRILL_EM | C14: CO2 Emission from burning of diesel fuel in Drilling machine | D14: Scope_1
A15: 14 | B15: LUBE_USE_EM | C15: CO2 Emission from use of lubricants in drilling | D15: Scope_1
A16: 15 | B16: ELECT_EM | C16: CO2 Emission from consumption of electricity from the grid | D16: Scope_2
A17: 16 | B17: DRILL_BIL_PROD_EM | C17: CO2 Emission from production of Diamond tipped Steel Drill bits | D17: Scope_3
... A20: 19 | B20: HEMV_TYRE_PROD_EM | C20: CO2 Emission from production of Tyres of LMV | D20: Scope_3
A21: 20 | B21: LMV_TYRE_PROD_EM | C21: CO2 Emission from production of Tyres of HEMV | D21: Scope_3 | E21: Number of tyres for LMV, number and weight per tyre
A22: 21 | B22: BATT_PROD_EM | C22: CO2 Emission from production of Lead-Acid Batteries | D22: Scope_3
A23: 22 | B23: BLAST_PROD_EM | C23: CO2 Emission from production of ANFO explosives | D23: Scope_3
A24: 23 | B24: OXY_ACE_PROD_EM | C24: CO2 Emission from production of Electric Arc Electrode | D24: Scope_3
A25: 24 | B25: ELECT_ARC_PROD_EM | C25: CO2 Emission from production of oxy acetylene gas cylinders | D25: Scope_3 | E25: No Emission Factor
A26: 25 | B26: HDPE5_PROD_EM | C26: CO2 Emission from production of HDPE pipes for 3m and 5 inch (dia) | D26: Scope_3
A27: 26 | B27: HDPE4.5_PROD_EM | C27: CO2 Emission from production of HDPE pipes for 3m and 4.5 inch (dia) | D27: Scope_3
A28: 27 | B28: LPG_PROD_EM | C28: CO2 Emission from production of LPG cylinders | D28: Scope_3
A29: 28 | B29: FE_CHROM_PROD_EM | C29: CO2 Emission from production of ferro chrome alloy | D29: Scope_3
A30: 29 | B30: STEEL_PROD_EM | C30: CO2 Emission from production of Steel | D30: Scope_3
A31: 30 | B31: WTP_ELECT_EM | C31: CO2 Emission from use electricity in ETP | D31: Scope_3
A32: 31 | B32: QC_CHEM_PROD_EM | C32: CO2 Emission from production of chemicals used in Quality testing and control | D32: Scope_3 | E32: 12 out of 22 chemicals have EF
A33: 32 | B33: CHEM_ETP_PROD_EM | C33: CO2 Emission from production of chemicals used ETP | D33: Scope_3 | E33: No EF for polyelectrolyte
A34: 33 | B34: DISP_TYRE_EM | C34: CO2 Emission from disposal of Tyres | D34: Scope_3 | E34: Number of tyres for LMV, number and weight per tyre
A35: 34 | B35: DISP_LUBE_EM | C35: CO2 Emission from disposal of Lubricants | D35: Scope_3
A36: 35 | B36: TRANS_2WHS_EM | C36: CO2 Emission from commuting using 2-wheelers | D36: Scope_3
A37: 36 | B37: TRANS_4WHS_EM | C37: CO2 Emission from commuting using 4-wheelers | D37: Scope_3 | E37: Not used
A38: 37 | B38: TRANS_BUS_EM | C38: CO2 Emission from commuting using Buses | D38: Scope_3
A39: 38 | B39: TRANS_PLANE_EM | C39: CO2 Emission from Business Travel using Plane | D39: Scope_3
A40: 39 | B40: TRANS_LMV_EM | C40: CO2 Emission from Business Travel using LMV | D40: Scope_3 | E40: RO JK road
A41: 40 | B41: TRANS_6WHS_EM | C41: CO2 Emission from transportation of product using 6 wheeler vehicles | D41: Scope_3
A42: 41 | B42: TRANS_12_14WHS_EM | C42: CO2 Emission from transportation of product using 12/14 wheeler vehicles | D42: Scope_3
...

Sheet Emission_factor
A1: No. | B1: Process_code | C1: EF | D1: Unit | E1: Remarks
A2: 1 | B2: DG_CONS_EM | C2: 2.6679 | D2: kg CO₂-eq / litre of diesel fuel used
A3: 2 | B3: LPG_CONS_EM | C3: 1.53706 | D3: kg CO₂-eq / kg of LPG used
A4: 3 | B4: COMP_EM | C4: 0.439 | D4: kg CO₂-eq / kg of organic waste
A5: 4 | B5: BLAST_EM | E5: Not blasting in FY 2023-24
A6: 5 | B6: OVER_B_EM | C6: 1.12 | D6: kg CO₂-eq /ton of overburden
A7: 6 | B7: HEMV_FUEL_EM | C7: 2.6679 | D7: kg CO₂-eq/ litre of diesel fuel used
A8: 7 | B8: LMV_EM_D | C8: 2.6679 | D8: kg CO₂-eq / litre of diesel fuel used
A9: 8 | B9: LMV_EM_G | C9: 2.3449 | D9: kg CO₂-eq / litre of petrol fuel used
A10: 9 | B10: PUMP_DEW_EM | C10: 2.6679 | D10: kg CO₂-eq / litre of diesel fuel used
A11: 10 | B11: PORT_DG_EM | C11: 2.6679 | D11: kg CO₂-eq / litre of diesel fuel used
A12: 11 | B12: AC_R32_EM | C12: 2088 | D12: kg CO₂-eq/kg of refrigerant leaked (R32)
A13: 12 | B13: OXY_ACE_EM | C13: 3.3846 | D13: kg CO₂-eq/kg for acetylene
A14: 13 | B14: LUBE_USE_EM | C14: 0.528 | D14: kg CO₂-eq/litre of lubricants used
A15: 14 | B15: ELECT_EM | C15: 0.830851 | D15: kg CO₂-eq/kWh consumed
A16: 15 | B16: DRILL_BIL_PROD_EM | C16: 2.64 | D16: kg CO₂-eq/kg of Crude steel produced
A17: 16 | B17: LUBE_PROD_EM | C17: 2.48 | D17: kg CO₂-eq/litre of lubricant produced
... A23: 22 | B23: BATT_PROD_EM | C23: 2 | D23: kg CO₂-eq/ kWh power delivered
A24: 23 | B24: BLAST_PROD_EM | C24: 1.9 | D24: kg CO₂-eq/kg of explosives | E24: Not blasting in FY 2023-24
A25: 24 | B25: OXY_ACE_PROD_EM | C25: 3.23 | D25: kg CO₂-eq/ kg of acetylene produced
A26: 25 | B26: ELECT_ARC_PROD_EM | E26: No definite source
A27: 26 | B27: HDPE5_PROD_EM | C27: 7.667 | D27: kg CO₂-eq/m of pipe
A28: 27 | B28: HDPE4.5_PROD_EM | C28: 6 | D28: kg CO₂-eq/m of pipe
A29: 28 | B29: LPG_PROD_EM | C29: 5.35 | D29: kg CO₂-eq/ unit wt of cylinder
A30: 29 | B30: FE_CHROM_PROD_EM | C30: 5.3 | D30: kg CO₂-eq/kg FeCr | E30: Assumption 50% ore used in Steel prod
A31: 30 | B31: STEEL_PROD_EM | C31: 2.64 | D31: kgCO2/kg of Crude steel produced | E31: Assumption 50% ore used in FeCr prod using SAF process
A32: 31 | B32: WTP_ELECT_EM | C32: 0.830851 | D32: kg CO₂-eq/kWh consumed
A33: 32 | B33: QC_CHEM_PROD_EM | C33: 1.3533333 | D33: kg CO₂-eq/kg consumed | E33: Mean Emission Factor
A34: 33 | B34: CHEM_ETP_PROD_EM | C34: =C36+C35 -> 1.4482 | D34: kg CO₂-eq/kg consumed | E34: No emission factor for polyelectrolyte
A35: 34 | B35: CHEM1_ETP_PROD_EM | C35: 0.3282 | D35: kg CO₂-eq/kg consumed
A36: 35 | B36: CHEM2_ETP_PROD_EM | C36: 1.12 | D36: kg CO₂-eq/kg consumed
A37: 36 | B37: DISP_TYRE_EM | C37: 100 | D37: kg CO₂-eq/ton consumed
A38: 37 | B38: DISP_LUBE_EM | C38: 2.64 | D38: kg CO₂-eq/litre consumed
A39: 38 | B39: DISP_ENG_OIL_EM | C39: 2.64 | D39: kg CO₂-eq/litre consumed
A40: 39 | B40: DIS_GEAR_OIL_EM | C40: 2.64 | D40: kg CO₂-eq/litre consumed
A41: 40 | B41: TRANS_2WHS_EM | C41: 0.034016667 | D41: kg CO₂-eq/ km | E41: average emission of bikes and scooters < 200 cc
A42: 41 | B42: TRANS_4WHS_G_EM | C42: 0.17783333 | D42: kg CO₂-eq/ km | E42: average emission of all petrol based vehicles ( >800 and < 3000 cc)
A43: 42 | B43: TRANS_4WHS_D_EM | C43: 0.17783766 | D43: kg CO₂-eq/ km | E43: average emission of all diesel based vehicles ( >800 and < 3000 cc)
A44: 43 | B44: TRANS_BUS_EM | C44: 0.01516 | D44: kg CO₂-eq/pax km | E44: Average 30 pax bus
A45: 44 | B45: TRANS_PLANE_EM | C45: 0.121 | D45: kg CO₂-eq/pax km
...

Sheet Carbon_footprint
A1: No. | B1: Process_code | C1: Scope | D1: Total_emission (kgCO2) | E1: Total_emission (kTCO2)
A2: 1 | B2: DG_CONS_EM | C2: 1 | D2: =DG_CONS_EM!G38 -> 5186.3976 | E2: =D2/10^6 -> 0.0051863976 | F2: =(D2/$D$46)*100 -> 0.041309482 | H2: Total Emission (KT/yr) | I2: =(SUM(D2:D45))/10^6 -> 12.554981
A3: 2 | B3: LPG_CONS_EM | C3: 1 | D3: =LPG_CONS_EM!H14 -> 187.21391 | E3: =D3/10^6 -> 0.00018721391 | F3: =(D3/$D$46)*100 -> 0.0014911525 | G3: 1 | H3: Scope1 | I3: =(SUMIF(C2:C45,G3,D2:D45))/10^6 -> 7.4465815
A4: 3 | B4: COMP_EM | C4: 1 | D4: 190.965 | E4: =D4/10^6 -> 0.000190965 | F4: =(D4/$D$46)*100 -> 0.0015210298 | G4: 2 | H4: Scope 2 | I4: =(SUMIF(C2:C45,G4,D2:D45))/10^6 -> 0.20549072
A5: 4 | B5: BLAST_EM | C5: 1 | D5: 0 | E5: =D5/10^6 -> 0 | F5: =(D5/$D$46)*100 -> 0 | G5: 3 | H5: Scope 3 | I5: =(SUMIF(C2:C45,G5,D2:D45))/10^6 -> 4.9029087
A6: 5 | B6: OVER_B_EM | C6: 1 | D6: =OVER_B_EM!G14 -> 1892496 | E6: =D6/10^6 -> 1.892496 | F6: =(D6/$D$46)*100 -> 15.073667
A7: 6 | B7: HEMV_FUEL_EM | C7: 1 | D7: =HEMV_FUEL_EM!H52 -> 3642593.8 | E7: =D7/10^6 -> 3.6425938 | F7: =(D7/$D$46)*100 -> 29.013137
A8: 7 | B8: LMV_EM_D | C8: 1 | D8: =LMV_EM_D!H16 -> 179916.45 | E8: =D8/10^6 -> 0.17991645 | F8: =(D8/$D$46)*100 -> 1.4330285
A9: 8 | B9: LMV_EM_G | C9: 1 | D9: =LMV_EM_G!A1 -> 0 | E9: =D9/10^6 -> 0 | F9: =(D9/$D$46)*100 -> 0
A10: 9 | B10: PUMP_DEW_EM | C10: 1 | D10: =PUMP_DEW_EM!H5 -> 1361973.6 | E10: =D10/10^6 -> 1.3619736 | F10: =(D10/$D$46)*100 -> 10.848074
A11: 10 | B11: PORT_DG_EM | C11: 1 | D11: =PORT_DG_EM!H11 -> 56102.677 | E11: =D11/10^6 -> 0.056102677 | F11: =(D11/$D$46)*100 -> 0.44685593
A12: 11 | B12: AC_R32_EM | C12: 1 | D12: =AC_R32_EM!J14 -> 22675.68 | E12: =D12/10^6 -> 0.02267568 | F12: =(D12/$D$46)*100 -> 0.18061103
A13: 12 | B13: OXY_ACE_EM | C13: 1 | D13: =OXY_ACE_EM!I2 -> 1756.3312 | E13: =D13/10^6 -> 0.0017563312 | F13: =(D13/$D$46)*100 -> 0.013989119
A14: 13 | B14: DIESEL_DRILL_EM | C14: 1 | D14: =DIESEL_DRILL_EM!E2 -> 230506.56 | E14: =D14/10^6 -> 0.23050656 | F14: =(D14/$D$46)*100 -> 1.835977
A15: 14 | B15: LUBE_USE_EM | C15: 1 | D15: =LUBE_USE_EM!F6 -> 30420.72 | E15: =D15/10^6 -> 0.03042072 | F15: =(D15/$D$46)*100 -> 0.24230001
A16: 15 | B16: ELECT_EM | C16: 2 | D16: =ELECT_EM!E2 -> 205490.72 | E16: =D16/10^6 -> 0.20549072 | F16: =(D16/$D$46)*100 -> 1.6367267
A17: 16 | B17: DRILL_BIL_PROD_EM | C17: 3 | D17: =DRILL_BIL_PROD_EM!G4 -> 2772 | E17: =D17/10^6 -> 0.002772 | F17: =(D17/$D$46)*100 -> 0.022078887
A18: 17 | B18: LUBE_PROD_EM | C18: 3 | D18: =LUBE_PROD_EM!F6 -> 142885.2 | E18: =D18/10^6 -> 0.1428852 | F18: =(D18/$D$46)*100 -> 1.1380758
A19: 18 | B19: PVC_BOX_PROD_EM | C19: 3 | D19: =PVC_BOX_PROD_EM!G4 -> 26631.396 | E19: =D19/10^6 -> 0.026631396 | F19: =(D19/$D$46)*100 -> 0.21211817
A20: 19 | B20: HEMV_TYRE_PROD_EM | C20: 3 | D20: =HEMV_TYRE_PROD_EM!G2 -> 88075.96 | E20: =D20/10^6 -> 0.08807596 | F20: =(D20/$D$46)*100 -> 0.70152206
A21: 20 | B21: LMV_TYRE_PROD_EM | C21: 3 | D21: =LMV_TYRE_PROD_EM!A1 -> 0 | E21: =D21/10^6 -> 0 | F21: =(D21/$D$46)*100 -> 0
A22: 21 | B22: BATT_PROD_EM | C22: 3 | D22: =BATT_PROD_EM!I2 -> 43.2 | E22: =D22/10^6 -> 4.32e-05 | F22: =(D22/$D$46)*100 -> 0.00034408655
A23: 22 | B23: BLAST_PROD_EM | C23: 3 | D23: 0 | E23: =D23/10^6 -> 0 | F23: =(D23/$D$46)*100 -> 0
A24: 23 | B24: OXY_ACE_PROD_EM | C24: 3 | D24: =OXY_ACE_PROD_EM!J4 -> 10014.171 | E24: =D24/10^6 -> 0.010014171 | F24: =(D24/$D$46)*100 -> 0.079762537
A25: 24 | B25: ELECT_ARC_PROD_EM | C25: 3 | D25: 0 | E25: =D25/10^6 -> 0 | F25: =(D25/$D$46)*100 -> 0
A26: 25 | B26: HDPE5_PROD_EM | C26: 3 | D26: =HDPE5_PROD_EM!H2 -> 6900.3 | E26: =D26/10^6 -> 0.0069003 | F26: =(D26/$D$46)*100 -> 0.054960657
A27: 26 | B27: LPG_PROD_EM | C27: 3 | D27: =LPG_PROD_EM!J14 -> 2978.88 | E27: =D27/10^6 -> 0.00297888 | F27: =(D27/$D$46)*100 -> 0.023726679
A28: 27 | B28: FE_CHROM_PROD_EM | C28: 3 | D28: =FE_CHROM_PROD_EM!G14 -> 792774 | E28: =D28/10^6 -> 0.792774 | F28: =(D28/$D$46)*100 -> 6.3144182
A29: 28 | B29: STEEL_PROD_EM | C29: 3 | D29: =STEEL_PROD_EM!G14 -> 394891.2 | E29: =D29/10^6 -> 0.3948912 | F29: =(D29/$D$46)*100 -> 3.1452951
A30: 29 | B30: WTP_ELECT_EM | C30: 3 | D30: =WTP_ELECT_EM!G2 -> 551411.92 | E30: =D30/10^6 -> 0.55141192 | F30: =(D30/$D$46)*100 -> 4.3919774
A31: 30 | B31: QC_CHEM_PROD_EM | C31: 3 | D31: =QC_CHEM_PROD_EM!K14 -> 55.117469 | E31: =D31/10^6 -> 5.5117469e-05 | F31: =(D31/$D$46)*100 -> 0.00043900879
A32: 31 | B32: CHEM_ETP_PROD_EM | C32: 3 | D32: =CHEM_ETP_PROD_EM!E5 -> 14123.085 | E32: =D32/10^6 -> 0.014123085 | F32: =(D32/$D$46)*100 -> 0.1124899
A33: 32 | B33: DISP_TYRE_EM | C33: 3 | D33: =DISP_TYRE_EM!G4 -> 3168.2 | E33: =D33/10^6 -> 0.0031682 | F33: =(D33/$D$46)*100 -> 0.025234606
A34: 33 | B34: DISP_LUBE_EM | C34: 3 | D34: =DISP_LUBE_EM!F6 -> 152103.6 | E34: =D34/10^6 -> 0.1521036 | F34: =(D34/$D$46)*100 -> 1.2115001
A35: 34 | B35: TRANS_2WHS_EM | C35: 3 | D35: =TRANS_2WHS_EM!H3 -> 6358.8461 | E35: =D35/10^6 -> 0.0063588461 | F35: =(D35/$D$46)*100 -> 0.050647995
A36: 35 | B36: TRANS_4WHS_EM | C36: 3 | D36: 0 | E36: =D36/10^6 -> 0 | F36: =(D36/$D$46)*100 -> 0
A37: 36 | B37: TRANS_BUS_EM | C37: 3 | D37: =TRANS_BUS_EM!G2 -> 15062.963 | E37: =D37/10^6 -> 0.015062963 | F37: =(D37/$D$46)*100 -> 0.119976
A38: 37 | B38: TRANS_PLANE_EM | C38: 3 | D38: =TRANS_PLANE_EM!G6 -> 1572.758 | E38: =D38/10^6 -> 0.001572758 | F38: =(D38/$D$46)*100 -> 0.012526965
A39: 38 | B39: TRANS_LMV_EM | C39: 3 | D39: =TRANS_LMV_EM!H20 -> 806.31596 | E39: =D39/10^6 -> 0.00080631596 | F39: =(D39/$D$46)*100 -> 0.0064222795
A40: 39 | B40: TRANS_6WHS_EM | C40: 3 | D40: =TRANS_6WHS_EM!K543 -> 1477995.5 | E40: =D40/10^6 -> 1.4779955 | F40: =(D40/$D$46)*100 -> 11.772185
...

Sheet Increase in Capacity
A1: To model the increase in production from 0.3 million tonnes to 0.9 million tonnes of chromite ore, we need to identify the processes that will scale proportionally with production levels and those that may not increase linearly.
A2: Key Assumptions
A3: Linear Scaling | B3: Some processes, such as energy use, fuel consumption, and ore transportation, will scale directly with the increase in production. This means that as production triples (from 0.3 to 0.9 million tonnes), these processes will see a proportional increase in activity.
A4: Non-Linear Scaling | B4: Some processes, like infrastructure operations (administration, employee commuting, etc.), may not scale in the same way as the core mining activities.
A6: Processes Directly impacted by scaling , we can use the scaling factor of 3 ( 0.9/0.3)
A7: Processes Indirectly impacted by scaling, expert suggestion maybe assume > 3
A9: Process_code | B9: Process_desc | C9: Scope | D9: Scaling Factor | E9: Emission at 0.3 MTPA (kTonCO2/yr) | F9: Emission at 0.9 MTPA (kTonCO2/yr)
A10: DG_CONS_EM | B10: CO2 Emission from burning of diesel fuels in Diesel Generators | C10: 1 | D10: 3 | E10: =Carbon_footprint!E2 -> 0.0051863976 | F10: =E10*D10 -> 0.015559193
A11: LPG_CONS_EM | B11: CO2 Emission from burning of LPG Fuel | C11: 1 | D11: 3 | E11: =Carbon_footprint!E3 -> 0.00018721391 | F11: =E11*D11 -> 0.00056164172
A12: COMP_EM | B12: CO2 Emission from composting of organic waste | C12: 1 | D12: 3.05 | E12: =Carbon_footprint!E4 -> 0.000190965 | F12: =E12*D12 -> 0.00058244325
A13: BLAST_EM | B13: CO2 Emission from use of explosives | C13: 1 | D13: 3.2 | E13: =Carbon_footprint!E5 -> 0 | F13: =E13*D13 -> 0
A14: OVER_B_EM | B14: CO2 Emission from anaerobic digestion of overburden | C14: 1 | D14: 3.1 | E14: =Carbon_footprint!E6 -> 1.892496 | F14: =E14*D14 -> 5.8667377
A15: HEMV_FUEL_EM | B15: CO2 Emission from burning of diesel fuel in Heavy Earth Moving Vehicle | C15: 1 | D15: 3.2 | E15: =Carbon_footprint!E7 -> 3.6425938 | F15: =E15*D15 -> 11.6563
A16: LMV_EM_D | B16: CO2 Emission from burning of petrol fuel in Light Motor Vehicle | C16: 1 | D16: 3.05 | E16: =Carbon_footprint!E8 -> 0.17991645 | F16: =E16*D16 -> 0.54874518
A17: LMV_EM_G | B17: CO2 Emission from burning of diesel fuel in Light Motor Vehicle | C17: 1 | D17: 3.05 | E17: =Carbon_footprint!E9 -> 0 | F17: =E17*D17 -> 0
A18: PUMP_DEW_EM | B18: CO2 Emission from burning of diesel for pumping of water | C18: 1 | D18: 3 | E18: =Carbon_footprint!E10 -> 1.3619736 | F18: =E18*D18 -> 4.0859209
A19: PORT_DG_EM | B19: CO2 Emission from burning of diesel fuels in Portable Diesel Generators | C19: 1 | D19: 3 | E19: =Carbon_footprint!E11 -> 0.056102677 | F19: =E19*D19 -> 0.16830803
A20: AC_EM | B20: CO2 Emission from Leakages of Refrigants | C20: 1 | D20: 3 | E20: =Carbon_footprint!E12 -> 0.02267568 | F20: =E20*D20 -> 0.06802704
A21: OXY_ACE_EM | B21: CO2 Emission from burning oxy-acetylene cylinder for wielding | C21: 1 | D21: 3.1 | E21: =Carbon_footprint!E13 -> 0.0017563312 | F21: =E21*D21 -> 0.0054446268
... A53: CORE_TRANS_BB_EM | B53: CO2 Emission from transportation of processed Core drilling samples to lab in bhubaneswar | C53: 3 | D53: 3.1 | E53: =Carbon_footprint!E45 -> 0.020486899 | F53: =E53*D53 -> 0.063509386
D54: Total | E54: =SUM(E10:E53) -> 12.554981 | F54: =SUM(F10:F53) -> 39.394077
C55: 1 | D55: Scope 1 | E55: =SUMIF(C10:C53,C55,E10:E53) -> 7.4465815 | F55: =SUMIF(C10:C53,C55,F10:F53) -> 23.318095
C56: 2 | D56: Scope 2 | E56: =SUMIF(C10:C53,C56,E10:E53) -> 0.20549072 | F56: =SUMIF(C10:C53,C56,F10:F53) -> 0.65757031
C57: 3 | D57: Scope 3 | E57: =SUMIF(C10:C53,C57,E10:E53) -> 4.9029087 | F57: =SUMIF(C10:C53,C57,F10:F53) -> 15.418412
F58: kTCO2/yr

Sheet DG_CONS_EM
A1: Sl_no | B1: Process_code | C1: Sub_process_code | D1: Year | E1: Month | F1: Fuel_cons | G1: Emission
A2: 1 | B2: DG_CONS_EM | C2: DG_CONS_EM_OFF | D2: 2023 | E2: April | F2: 0 | G2: =F2*Emission_factor!$C$2 -> 0
A3: 2 | B3: DG_CONS_EM | C3: DG_CONS_EM_OFF | D3: 2023 | E3: May | F3: 0 | G3: =F3*Emission_factor!$C$2 -> 0
A4: 3 | B4: DG_CONS_EM | C4: DG_CONS_EM_OFF | D4: 2023 | E4: June | F4: 0 | G4: =F4*Emission_factor!$C$2 -> 0
A5: 4 | B5: DG_CONS_EM | C5: DG_CONS_EM_OFF | D5: 2023 | E5: July | F5: 0 | G5: =F5*Emission_factor!$C$2 -> 0
A6: 5 | B6: DG_CONS_EM | C6: DG_CONS_EM_OFF | D6: 2023 | E6: August | F6: 192 | G6: =F6*Emission_factor!$C$2 -> 512.2368
A7: 6 | B7: DG_CONS_EM | C7: DG_CONS_EM_OFF | D7: 2023 | E7: September | F7: 52 | G7: =F7*Emission_factor!$C$2 -> 138.7308
A8: 7 | B8: DG_CONS_EM | C8: DG_CONS_EM_OFF | D8: 2023 | E8: October | F8: 52 | G8: =F8*Emission_factor!$C$2 -> 138.7308
A9: 8 | B9: DG_CONS_EM | C9: DG_CONS_EM_OFF | D9: 2023 | E9: November | F9: 100 | G9: =F9*Emission_factor!$C$2 -> 266.79
A10: 9 | B10: DG_CONS_EM | C10: DG_CONS_EM_OFF | D10: 2023 | E10: December | F10: 100 | G10: =F10*Emission_factor!$C$2 -> 266.79
A11: 10 | B11: DG_CONS_EM | C11: DG_CONS_EM_OFF | D11: 2024 | E11: January | F11: 104 | G11: =F11*Emission_factor!$C$2 -> 277.4616
A12: 11 | B12: DG_CONS_EM | C12: DG_CONS_EM_OFF | D12: 2024 | E12: February | F12: 0 | G12: =F12*Emission_factor!$C$2 -> 0
A13: 12 | B13: DG_CONS_EM | C13: DG_CONS_EM_OFF | D13: 2024 | E13: March | F13: 48 | G13: =F13*Emission_factor!$C$2 -> 128.0592
... A37: 36 | B37: DG_CONS_EM | C37: DG_CONS_EM_WB2 | D37: 2024 | E37: March | F37: 48 | G37: =F37*Emission_factor!$C$2 -> 128.0592
A38: 35 | B38: DG_CONS_EM | C38: DG_CONS_EM_Total | F38: =SUM(F2:F37) -> 1944 | G38: =F38*Emission_factor!$C$2 -> 5186.3976
F39: litres | G39: Kg CO2

Sheet LPG_CONS_EM
A1: Sl_no | B1: Process_code | C1: Year | D1: Month | E1: LPG_no | F1: Weight_LPG | G1: Total_LPG_Cons | H1: Total_emission
A2: 1 | B2: LPG_CONS_EM | C2: 2023 | D2: April | E2: 0 | F2: 4.2 | G2: =F2*E2 -> 0 | H2: =G2*Emission_factor!$C$3 -> 0
A3: 2 | B3: LPG_CONS_EM | C3: 2023 | D3: May | E3: 6 | F3: 4.2 | G3: =F3*E3 -> 25.2 | H3: =G3*Emission_factor!$C$3 -> 38.733912
A4: 3 | B4: LPG_CONS_EM | C4: 2023 | D4: June | E4: 0 | F4: 4.2 | G4: =F4*E4 -> 0 | H4: =G4*Emission_factor!$C$3 -> 0
A5: 4 | B5: LPG_CONS_EM | C5: 2023 | D5: July | E5: 0 | F5: 4.2 | G5: =F5*E5 -> 0 | H5: =G5*Emission_factor!$C$3 -> 0
A6: 5 | B6: LPG_CONS_EM | C6: 2023 | D6: August | E6: 0 | F6: 4.2 | G6: =F6*E6 -> 0 | H6: =G6*Emission_factor!$C$3 -> 0
A7: 6 | B7: LPG_CONS_EM | C7: 2023 | D7: September | E7: 4 | F7: 4.2 | G7: =F7*E7 -> 16.8 | H7: =G7*Emission_factor!$C$3 -> 25.822608
A8: 7 | B8: LPG_CONS_EM | C8: 2023 | D8: October | E8: 5 | F8: 4.2 | G8: =F8*E8 -> 21 | H8: =G8*Emission_factor!$C$3 -> 32.27826
A9: 8 | B9: LPG_CONS_EM | C9: 2023 | D9: November | E9: 3 | F9: 4.2 | G9: =F9*E9 -> 12.6 | H9: =G9*Emission_factor!$C$3 -> 19.366956
A10: 9 | B10: LPG_CONS_EM | C10: 2023 | D10: December | E10: 3 | F10: 4.2 | G10: =F10*E10 -> 12.6 | H10: =G10*Emission_factor!$C$3 -> 19.366956
A11: 10 | B11: LPG_CONS_EM | C11: 2024 | D11: January | E11: 4 | F11: 4.2 | G11: =F11*E11 -> 16.8 | H11: =G11*Emission_factor!$C$3 -> 25.822608
A12: 11 | B12: LPG_CONS_EM | C12: 2024 | D12: February | E12: 3 | F12: 4.2 | G12: =F12*E12 -> 12.6 | H12: =G12*Emission_factor!$C$3 -> 19.366956
A13: 12 | B13: LPG_CONS_EM | C13: 2024 | D13: March | E13: 1 | F13: 4.2 | G13: =F13*E13 -> 4.2 | H13: =G13*Emission_factor!$C$3 -> 6.455652
E14: =SUM(E2:E13) -> 29 | G14: =SUM(G2:G13) -> 121.8 | H14: =G14*Emission_factor!$C$3 -> 187.21391
G15: Kg | H15: Kg CO2

Sheet COMP_EM
A1: Sl_no | B1: Process_code | C1: Compost_gen | D1: Total_emission
A2: 1 | B2: COMP_EM | C2: 435 | D2: =C2*Emission_factor!$C$4 -> 190.965
C3: Kg | D3: Kg CO2

Sheet HEMV_FUEL_EM
A1: Sl no | B1: Process_code | C1: Type | D1: Model | E1: Run_hrs | F1: Mileage | G1: Fuel_Con | H1: Total_emissions
A2: 1 | B2: HEMV_FUEL_EM | C2: TE-216 | D2: VOLVO/EC550EL | E2: 1208 | F2: 35.5 | G2: =E2*F2 -> 42884 | H2: =G2*Emission_factor!$C$7 -> 114410.22
A3: 2 | B3: HEMV_FUEL_EM | C3: TE 143 | D3: VOLVO/EC550EL | E3: 3040 | F3: 36 | G3: =E3*F3 -> 109440 | H3: =G3*Emission_factor!$C$7 -> 291974.98
A4: 3 | B4: HEMV_FUEL_EM | C4: TE-151 | D4: VOLVO/EC480DL | E4: 947 | F4: 33 | G4: =E4*F4 -> 31251 | H4: =G4*Emission_factor!$C$7 -> 83374.543
A5: 4 | B5: HEMV_FUEL_EM | C5: TE 159 | D5: VOLVO/EC550EL | E5: 3187 | F5: 35 | G5: =E5*F5 -> 111545 | H5: =G5*Emission_factor!$C$7 -> 297590.91
A6: 5 | B6: HEMV_FUEL_EM | C6: TE-38 | D6: VOLVO/EC480DL | E6: 267 | F6: 34 | G6: =E6*F6 -> 9078 | H6: =G6*Emission_factor!$C$7 -> 24219.196
A7: 6 | B7: HEMV_FUEL_EM | C7: TE-162 | D7: KOMATSU/PC130 | E7: 1835 | F7: 15 | G7: =E7*F7 -> 27525 | H7: =G7*Emission_factor!$C$7 -> 73433.947
A8: 7 | B8: HEMV_FUEL_EM | C8: TE-212 | D8: VOLVO/EC210 | E8: 1462 | F8: 23.7 | G8: =E8*F8 -> 34649.4 | H8: =G8*Emission_factor!$C$7 -> 92441.134
A9: 8 | B9: HEMV_FUEL_EM | C9: BD 32 | D9: CAT/D6R2 | E9: 2583 | F9: 26 | G9: =E9*F9 -> 67158 | H9: =G9*Emission_factor!$C$7 -> 179170.83
A10: 9 | B10: HEMV_FUEL_EM | C10: BD 23 | D10: CAT/D6R2 | E10: 1734 | F10: 27 | G10: =E10*F10 -> 46818 | H10: =G10*Emission_factor!$C$7 -> 124905.74
A11: 10 | B11: HEMV_FUEL_EM | C11: GD-20 | D11: SDLG/G9190H | E11: 2495 | F11: 15 | G11: =E11*F11 -> 37425 | H11: =G11*Emission_factor!$C$7 -> 99846.158
A12: 11 | B12: HEMV_FUEL_EM | C12: HDPV-121 | D12: VOLVO/FMX440 | E12: 929 | F12: 15 | G12: =E12*F12 -> 13935 | H12: =G12*Emission_factor!$C$7 -> 37177.186
A13: 12 | B13: HEMV_FUEL_EM | C13: HDPV-122 | D13: VOLVO/FMX440 | E13: 426 | F13: 14.5 | G13: =E13*F13 -> 6177 | H13: =G13*Emission_factor!$C$7 -> 16479.618
... A51: 50 | B51: HEMV_FUEL_EM | C51: SVAN -22 | D51: TATA/ULTRA 1918 | E51: 1516 | F51: 5 | G51: =E51*F51 -> 7580 | H51: =G51*Emission_factor!$C$7 -> 20222.682
F52: Total | G52: =SUM(G2:G51) -> 1365341.2 | H52: =G52*Emission_factor!$C$7 -> 3642593.8
G53: Litres | H53: Kg CO2

Sheet OVER_B_EM
A1: Sl_no | B1: Process_code | C1: Year | D1: Month | E1: m3 | F1: T | G1: Total_emission
A2: 1 | B2: OVER_B_EM | C2: 2023 | D2: Apr | E2: 97876.18 | F2: 89654 | G2: =F2*Emission_factor!$C$6 -> 100412.48
A3: 2 | B3: OVER_B_EM | C3: 2023 | D3: May | E3: 129448 | F3: 116812 | G3: =F3*Emission_factor!$C$6 -> 130829.44
A4: 3 | B4: OVER_B_EM | C4: 2023 | D4: Jun | E4: 59295 | F4: 8319 | G4: =F4*Emission_factor!$C$6 -> 9317.28
A5: 4 | B5: OVER_B_EM | C5: 2023 | D5: Jul | E5: 83449.45 | F5: 78308 | G5: =F5*Emission_factor!$C$6 -> 87704.96
A6: 5 | B6: OVER_B_EM | C6: 2023 | D6: Aug | E6: 72649.55 | F6: 71287 | G6: =F6*Emission_factor!$C$6 -> 79841.44
A7: 6 | B7: OVER_B_EM | C7: 2023 | D7: Sep | E7: 74403 | F7: 74403 | G7: =F7*Emission_factor!$C$6 -> 83331.36
A8: 7 | B8: OVER_B_EM | C8: 2023 | D8: Oct | E8: 98428.91 | F8: 96534 | G8: =F8*Emission_factor!$C$6 -> 108118.08
A9: 8 | B9: OVER_B_EM | C9: 2023 | D9: Nov | E9: 174239.36 | F9: 167347 | G9: =F9*Emission_factor!$C$6 -> 187428.64
A10: 9 | B10: OVER_B_EM | C10: 2023 | D10: Dec | E10: 279482.73 | F10: 266970 | G10: =F10*Emission_factor!$C$6 -> 299006.4
A11: 10 | B11: OVER_B_EM | C11: 2024 | D11: Jan | E11: 285389.73 | F11: 257709 | G11: =F11*Emission_factor!$C$6 -> 288634.08
A12: 11 | B12: OVER_B_EM | C12: 2024 | D12: Feb | E12: 274092.36 | F12: 240932 | G12: =F12*Emission_factor!$C$6 -> 269843.84
A13: 12 | B13: OVER_B_EM | C13: 2024 | D13: Mar | E13: 224152.51 | F13: 221453.6 | G13: =F13*Emission_factor!$C$6 -> 248028.03
D14: Total | E14: =SUM(E2:E13) -> 1852906.8 | F14: =SUM(F2:F13) -> 1689728.6 | G14: =F14*Emission_factor!$C$6 -> 1892496
F15: Ton | G15: Kg CO2

Sheet LMV_EM_D
A1: Sl no | B1: Process_code | C1: Type | D1: Model | E1: Run_hrs | F1: Mileage | G1: Fuel_Con | H1: Total_emissions
A2: 1 | B2: LMV_EM_D | C2: LMV-176 | D2: MAHINDRA/M2DICR | E2: 41083 | F2: 8.4 | G2: =E2/F2 -> 4890.8333 | H2: =G2*Emission_factor!$C$8 -> 13048.254
A3: 2 | B3: LMV_EM_D | C3: LMV-180 | D3: MAHINDRA/M2DICR | E3: 28816 | F3: 8.8 | G3: =E3/F3 -> 3274.5455 | H3: =G3*Emission_factor!$C$8 -> 8736.1598
A4: 3 | B4: LMV_EM_D | D4: BOLERO | E4: 53253 | F4: 11 | G4: =E4/F4 -> 4841.1818 | H4: =G4*Emission_factor!$C$8 -> 12915.789
A5: 4 | B5: LMV_EM_D | D5: BOLERO | E5: 41723 | F5: 11 | G5: =E5/F5 -> 3793 | H5: =G5*Emission_factor!$C$8 -> 10119.345
A6: 5 | B6: LMV_EM_D | D6: BOLERO | E6: 22275 | F6: 11 | G6: =E6/F6 -> 2025 | H6: =G6*Emission_factor!$C$8 -> 5402.4975
A7: 6 | B7: LMV_EM_D | D7: BOLERO | E7: 9735 | F7: 11 | G7: =E7/F7 -> 885 | H7: =G7*Emission_factor!$C$8 -> 2361.0915
A8: 7 | B8: LMV_EM_D | D8: BOLERO | E8: 10371 | F8: 11 | G8: =E8/F8 -> 942.81818 | H8: =G8*Emission_factor!$C$8 -> 2515.3446
A9: 8 | B9: LMV_EM_D | D9: BOLERO | E9: 29616 | F9: 11 | G9: =E9/F9 -> 2692.3636 | H9: =G9*Emission_factor!$C$8 -> 7182.9569
A10: 9 | B10: LMV_EM_D | D10: BOLERO | E10: 17668 | F10: 11 | G10: =E10/F10 -> 1606.1818 | H10: =G10*Emission_factor!$C$8 -> 4285.1325
A11: 10 | B11: LMV_EM_D | D11: CAMPER | E11: 39493 | F11: 7 | G11: =E11/F11 -> 5641.8571 | H11: =G11*Emission_factor!$C$8 -> 15051.911
A12: 11 | B12: LMV_EM_D | D12: CAMPER | E12: 41083 | F12: 8.43 | G12: =E12/F12 -> 4873.4282 | H12: =G12*Emission_factor!$C$8 -> 13001.819
A13: 12 | B13: LMV_EM_D | D13: CAMPER | E13: 28816 | F13: 8.79 | G13: =E13/F13 -> 3278.2708 | H13: =G13*Emission_factor!$C$8 -> 8746.0986
A14: 13 | B14: LMV_EM_D | D14: AMBULANCE | E14: 25223 | F14: 11 | G14: =E14/F14 -> 2293 | H14: =G14*Emission_factor!$C$8 -> 6117.4947
A15: 14 | B15: LMV_EM_D | D15: BOLERO_WATER | G15: 26400 | H15: =G15*Emission_factor!$C$8 -> 70432.56
F16: Total | G16: =SUM(G2:G15) -> 67437.48 | H16: =G16*Emission_factor!$C$8 -> 179916.45
G17: Liters | H17: Kg CO2

Sheet LMV_EM_G

Sheet PUMP_DEW_EM
A1: Sl no | B1: Process_code | C1: Type | D1: Model | E1: Run_Hrs | F1: Per_hr | G1: Fuel_cons | H1: Total_emissions
A2: 1 | B2: PUMP_DEW_EM | C2: 200 HP PUMP | D2: KIRLOSKAR/198 HP | E2: 4648 | F2: 37 | G2: =E2*F2 -> 171976 | H2: =G2*Emission_factor!$C$10 -> 458814.77
A3: 2 | B3: PUMP_DEW_EM | C3: 391 HP PUMP | D3: GREAVES/391 HP | E3: 2096 | F3: 43 | G3: =E3*F3 -> 90128 | H3: =G3*Emission_factor!$C$10 -> 240452.49
A4: 3 | B4: PUMP_DEW_EM | C4: 396 HP PUMP | D4: GREAVES/396 HP | E4: 5400 | F4: 46 | G4: =E4*F4 -> 248400 | H4: =G4*Emission_factor!$C$10 -> 662706.36
F5: Total | G5: =SUM(G2:G4) -> 510504 | H5: =G5*Emission_factor!$C$10 -> 1361973.6
G6: Liters | H6: kg CO2

Sheet PORT_DG_EM
A1: Sl no | B1: Process_code | C1: Type | D1: Model | E1: Run_hr | F1: Per_Hr | G1: Fuel_Cons | H1: Total_emission
A2: 1 | B2: PORT_DG_EM | C2: LS - 53 | D2: ATLAS COPCO | E2: 2293.82 | F2: 0.7 | G2: =E2*F2 -> 1605.674 | H2: =G2*Emission_factor!$C$10 -> 4283.7777
A3: 2 | B3: PORT_DG_EM | C3: LS - 77 | D3: ATLAS COPCO | E3: 2658 | F3: 0.7 | G3: =E3*F3 -> 1860.6 | H3: =G3*Emission_factor!$C$10 -> 4963.8947
A4: 3 | B4: PORT_DG_EM | C4: LS - 99 | D4: ATLAS COPCO | E4: 2214.3 | F4: 0.7 | G4: =E4*F4 -> 1550.01 | H4: =G4*Emission_factor!$C$10 -> 4135.2717
A5: 4 | B5: PORT_DG_EM | C5: LS - 101 | D5: ATLAS COPCO | E5: 2810.23 | F5: 0.8 | G5: =E5*F5 -> 2248.184 | H5: =G5*Emission_factor!$C$10 -> 5997.9301
A6: 5 | B6: PORT_DG_EM | C6: LS - 251 | D6: ASKA | E6: 2967.56 | F6: 1 | G6: =E6*F6 -> 2967.56 | H6: =G6*Emission_factor!$C$10 -> 7917.1533
A7: 6 | B7: PORT_DG_EM | C7: LS - 252 | D7: ASKA | E7: 3247.58 | F7: 1 | G7: =E7*F7 -> 3247.58 | H7: =G7*Emission_factor!$C$10 -> 8664.2187
A8: 7 | B8: PORT_DG_EM | C8: LS-253 | D8: ATLAS COPCO | E8: 2499.4 | F8: 1 | G8: =E8*F8 -> 2499.4 | H8: =G8*Emission_factor!$C$10 -> 6668.1493
A9: 8 | B9: PORT_DG_EM | C9: LS-254 | D9: ATLAS COPCO | E9: 2707.7 | F9: 1 | G9: =E9*F9 -> 2707.7 | H9: =G9*Emission_factor!$C$10 -> 7223.8728
A10: 9 | B10: PORT_DG_EM | C10: LS-255 | D10: ATLAS COPCO | E10: 2602.3 | F10: 0.9 | G10: =E10*F10 -> 2342.07 | H10: =G10*Emission_factor!$C$10 -> 6248.4086
F11: Total | G11: =SUM(G2:G10) -> 21028.778 | H11: =G11*Emission_factor!$C$10 -> 56102.677
G12: Liters

Sheet AC_R32_EM
A1: Sl | B1: Process_code | C1: Area | D1: no | E1: Tonnage | F1: Wattage (W) | G1: Run_Time | H1: Energy (Wh) | I1: Leakage (kg) | J1: Total_emissions
A2: 1 | B2: AC_R32_EM | C2: MM | D2: 1 | E2: 1.5 | F2: 1500 | G2: 8 | H2: =G2*F2 -> 12000 | I2: =(0.68+1.13)/2 -> 0.905 | J2: =I2*Emission_factor!$C$12 -> 1889.64
A3: 2 | B3: AC_R32_EM | C3: PS | D3: 1 | E3: 1.5 | F3: 1500 | G3: 8 | H3: =G3*F3 -> 12000 | I3: =(0.68+1.13)/2 -> 0.905 | J3: =I3*Emission_factor!$C$12 -> 1889.64
A4: 3 | B4: AC_R32_EM | C4: Ele | D4: 1 | E4: 1.5 | F4: 1500 | G4: 8 | H4: =G4*F4 -> 12000 | I4: =(0.68+1.13)/2 -> 0.905 | J4: =I4*Emission_factor!$C$12 -> 1889.64
A5: 4 | B5: AC_R32_EM | C5: F&E | D5: 1 | E5: 1.5 | F5: 1500 | G5: 8 | H5: =G5*F5 -> 12000 | I5: =(0.68+1.13)/2 -> 0.905 | J5: =I5*Emission_factor!$C$12 -> 1889.64
A6: 5 | B6: AC_R32_EM | C6: Looby | D6: 2 | E6: 1.5 | F6: 1500 | G6: 8 | H6: =G6*F6 -> 12000 | I6: =(0.68+1.13)/2 -> 0.905 | J6: =I6*Emission_factor!$C$12 -> 1889.64
A7: 6 | B7: AC_R32_EM | C7: Finance_1 | D7: 1 | E7: 1.5 | F7: 1500 | G7: 8 | H7: =G7*F7 -> 12000 | I7: =(0.68+1.13)/2 -> 0.905 | J7: =I7*Emission_factor!$C$12 -> 1889.64
A8: 7 | B8: AC_R32_EM | C8: Min | D8: 1 | E8: 1.5 | F8: 1500 | G8: 8 | H8: =G8*F8 -> 12000 | I8: =(0.68+1.13)/2 -> 0.905 | J8: =I8*Emission_factor!$C$12 -> 1889.64
A9: 8 | B9: AC_R32_EM | C9: Sur and Safety | D9: 1 | E9: 1.5 | F9: 1500 | G9: 8 | H9: =G9*F9 -> 12000 | I9: =(0.68+1.13)/2 -> 0.905 | J9: =I9*Emission_factor!$C$12 -> 1889.64
A10: 9 | B10: AC_R32_EM | C10: Geo and Mech | D10: 1 | E10: 1.5 | F10: 1500 | G10: 8 | H10: =G10*F10 -> 12000 | I10: =(0.68+1.13)/2 -> 0.905 | J10: =I10*Emission_factor!$C$12 -> 1889.64
A11: 10 | B11: AC_R32_EM | C11: Finance_2 | D11: 1 | E11: 1.5 | F11: 1500 | G11: 8 | H11: =G11*F11 -> 12000 | I11: =(0.68+1.13)/2 -> 0.905 | J11: =I11*Emission_factor!$C$12 -> 1889.64
A12: 11 | B12: AC_R32_EM | C12: Transport | D12: 1 | E12: 1.5 | F12: 1500 | G12: 8 | H12: =G12*F12 -> 12000 | I12: =(0.68+1.13)/2 -> 0.905 | J12: =I12*Emission_factor!$C$12 -> 1889.64
A13: 12 | B13: AC_R32_EM | C13: Step | D13: 1 | E13: 1.5 | F13: 1500 | G13: 8 | H13: =G13*F13 -> 12000 | I13: =(0.68+1.13)/2 -> 0.905 | J13: =I13*Emission_factor!$C$12 -> 1889.64
D14: =SUM(D2:D13) -> 13 | G14: Total | H14: =SUM(H2:H13)/1000 -> 144 | I14: =SUM(I2:I13) -> 10.86 | J14: =I14*Emission_factor!$C$12 -> 22675.68
I15: kg | J15: kgCO2

Sheet OXY_ACE_EM
A1: Sl NO | B1: Process_code | C1: Type | D1: Weight of cylinder | E1: No of Cylinder | F1: Volume of gas (m3) | G1: Weight of gas | H1: Total weight-gas | I1: Total_emission
A2: 1 | B2: OXY_ACE_EM | C2: DA | D2: 89 | E2: 48 | F2: 9.9 | G2: 10.8108 | H2: 518.9184 | I2: =H2*Emission_factor!C13 -> 1756.3312
A3: 2 | B3: OXY_ACE_EM | C3: Oxygen | D3: 50 | E3: 48 | F3: 11 | G3: 15.719 | H3: 754.512
I4: kgCO2

Sheet DIESEL_DRILL_EM
A1: Sl no | B1: Process_code | C1: No of Drills | D1: Tot_Fuel_cons | E1: Total_emission
A2: 1 | B2: DIESEL_DRILL_EM | C2: 3 | D2: 86400 | E2: =D2*Emission_factor!C2 -> 230506.56
D3: Ltrs | E3: kgCO2

Sheet LUBE_USE_EM
A1: Sl NO | B1: Process_code | C1: Type | D1: Sub_process | E1: Annual_cons | F1: Total_Emissions
A2: 1 | B2: LUBE_USE_EM | C2: Engine_oil | D2: Drilling | E2: 1800 | F2: =E2*Emission_factor!$C$14 -> 950.4
A3: 2 | B3: LUBE_USE_EM | C3: Gear Oil | D3: Drilling | E3: 900 | F3: =E3*Emission_factor!$C$14 -> 475.2
A4: 3 | B4: LUBE_USE_EM | C4: Engine_oil | D4: Vehicle | E4: 50947 | F4: =E4*Emission_factor!$C$14 -> 26900.016
A5: 4 | B5: LUBE_USE_EM | C5: Gear Oil | D5: Vehicle | E5: 3968 | F5: =E5*Emission_factor!$C$14 -> 2095.104
C6: Total | E6: =SUM(E2:E5) -> 57615 | F6: =E6*Emission_factor!$C$14 -> 30420.72
E7: Ltrs | F7: kgCO2

Sheet ELECT_EM
A1: Sl_no | B1: Process_code | C1: Type | D1: Total_Consumption | E1: Total Emissions
A2: 1 | B2: ELECT_EM | C2: Overall | D2: 247325.6 | E2: =D2*Emission_factor!$C$15 -> 205490.72
A3: 2 | B3: ELECT_EM | C3: Admin_building | D3: 114274.3 | E3: =D3*Emission_factor!$C$15 -> 94944.916
D4: kWh | E4: kgCO2

Sheet DRILL_BIL_PROD_EM
A1: Sl_no | B1: Process_code | C1: Type | D1: Weight | E1: No | F1: Total_wt | G1: Total_emissions
A2: 1 | B2: DRILL_BIL_PROD_EM | C2: HQ3 Imp Dia Bit | D2: 2.5 | E2: 300 | F2: =E2*D2 -> 750 | G2: =F2*Emission_factor!$C$16 -> 1980
C3: NQ3 Imp Dia Bit | D3: 2.5 | E3: 120 | F3: =E3*D3 -> 300 | G3: =F3*Emission_factor!$C$16 -> 792
E4: Total | F4: =SUM(F2:F3) -> 1050 | G4: =F4*Emission_factor!$C$16 -> 2772
F5: kg | G5: kgCO2

Sheet LUBE_PROD_EM
A1: Sl NO | B1: Process_code | C1: Type | D1: Sub_process | E1: Annual_cons | F1: Total_emissions
A2: 1 | B2: LUBE_PROD_EM | C2: Engine_oil | D2: Drilling | E2: 1800 | F2: =E2*Emission_factor!$C$17 -> 4464
A3: 2 | B3: LUBE_PROD_EM | C3: Gear Oil | D3: Drilling | E3: 900 | F3: =E3*Emission_factor!$C$17 -> 2232
A4: 3 | B4: LUBE_PROD_EM | C4: Engine_oil | D4: Vehicle | E4: 50947 | F4: =E4*Emission_factor!$C$17 -> 126348.56
A5: 4 | B5: LUBE_PROD_EM | C5: Gear Oil | D5: Vehicle | E5: 3968 | F5: =E5*Emission_factor!$C$17 -> 9840.64
C6: Total | E6: 57615 | F6: =E6*Emission_factor!$C$17 -> 142885.2
E7: ltrs | F7: kgCO2

Sheet PVC_BOX_PROD_EM
A1: Sl_no | B1: Process_code | C1: Box_type | D1: Total_number | E1: wt_unit | F1: Total_wt | G1: Total_emissions
A2: 1 | B2: PVC_BOX_PROD_EM | C2: HQ | D2: 916 | E2: =F2/D2 -> 2.8 | F2: 2564.8 | G2: =F2*Emission_factor!$C$18 -> 20082.384
A3: 2 | B3: PVC_BOX_PROD_EM | C3: NQ | D3: 321 | E3: =F3/D3 -> 2.6056075 | F3: 836.4 | G3: =F3*Emission_factor!$C$18 -> 6549.012
E4: Total | F4: =SUM(F2:F3) -> 3401.2 | G4: =F4*Emission_factor!$C$18 -> 26631.396
F5: kg | G5: kgCO2

Sheet HEMV_TYRE_PROD_EM
A1: sl_no | B1: Process_code | C1: Type | D1: No | E1: Weight | F1: Total_weight | G1: Total_emission
A2: 1 | B2: HEMV_TYRE_PROD_EM | C2: Tyre | D2: 511 | E2: 62 | F2: =511*62 -> 31682 | G2: =F2*Emission_factor!C21 -> 88075.96
F3: Kg | G3: kgCO2

Sheet LMV_TYRE_PROD_EM

Sheet BATT_PROD_EM
A1: Sl_no | B1: Process_code | C1: Batt_volt (V) | D1: Batt_cap (AH) | E1: No | F1: Model | G1: Unit_Power (kWh) | H1: Power | I1: Total_emissions
A2: 1 | B2: BATT_PROD_EM | C2: 12 | D2: 150 | E2: 12 | F2: 1500 MHD | G2: 1.8 | H2: =G2*E2 -> 21.6 | I2: =H2*Emission_factor!C23 -> 43.2
H3: kWh | I3: kgCO2

Sheet BLAST_PROD_EM
A1: Sl_no | B1: Process_code | C1: Type | D1: Chem | E1: quantity
A2: 1 | B2: BLAST_PROD_EM | C2: Expo Prime | D2: Amonium Nitrate(ANFO) | E2: 1000
A3: 2 | B3: BLAST_PROD_EM | C3: Expo Gel | D3: Amonium Nitrate(ANFO) | E3: 500
E4: =SUM(E2:E3) -> 1500
E5: kg

Sheet OXY_ACE_PROD_EM
A1: Sl NO | B1: Process_code | C1: Type | D1: Weight of cylinder | E1: No of Cylinder | F1: Tot_wt_cyln | G1: Volume of gas (m3) | H1: Weight of gas | I1: Total weight-gas | J1: Total_emission
A2: 1 | B2: OXY_ACE_EM | C2: DA | D2: 50 | E2: 48 | F2: =D2*E2 -> 2400 | G2: 9.9 | H2: =1.092*G2 -> 10.8108 | I2: =E2*H2 -> 518.9184 | J2: =(I2*Emission_factor!C25)+(Emission_factor!C51*F2) -> 5756.1064 | K2: A-line | L2: estimated
A3: 2 | B3: OXY_ACE_EM | C3: Oxygen | D3: 50 | E3: 48 | F3: =D3*E3 -> 2400 | G3: 11 | H3: =1.429*G3 -> 15.719 | I3: =E3*H3 -> 754.512 | J3: =(I3*Emission_factor!C52)+(OXY_ACE_PROD_EM!F3*Emission_factor!C51) -> 4258.0648
I4: Total | J4: =J2+J3 -> 10014.171
J5: kg CO2

Sheet ELECT_ARC_PROD_EM
A1: Sl_no | B1: Process_code | C1: Type | D1: No | E1: Weight_unit | F1: Total_Weight
A2: 1 | B2: ELECT_ARC_PROD_EM | C2: Electrode | D2: 5000 | E2: 22.7 | F2: =(E2*D2)/1000 -> 113.5 | G2: estimated
F3: kg

Sheet HDPE5_PROD_EM
A1: Sl_no | B1: Process_code | C1: Type | D1: No | E1: Dia (inch) | F1: Lenth (m) | G1: Total Length | H1: Total_emissions
B2: HDPE5_PROD_EM | C2: HPDE | D2: 150 | E2: 6 | F2: 6 | G2: =D2*F2 -> 900 | H2: =G2*Emission_factor!C27 -> 6900.3 | I2: Confirm
G3: m | H3: kgCO2

Sheet LPG_PROD_EM
A1: Sl_no | B1: Process_code | C1: Year | D1: Month | E1: LPG_no | F1: Weight_LPG | G1: Weight of Cylinder | H1: Total_LPG_Cons | I1: Total_wt_cylin | J1: Total_emission
A2: 1 | B2: LPG_CONS_EM | C2: 2023 | D2: April | E2: 0 | F2: 4.2 | G2: 19.2 | H2: 0 | I2: =G2*E2 -> 0 | J2: =I2*Emission_factor!$C$29 -> 0
A3: 2 | B3: LPG_CONS_EM | C3: 2023 | D3: May | E3: 6 | F3: 4.2 | G3: 19.2 | H3: 25.2 | I3: =G3*E3 -> 115.2 | J3: =I3*Emission_factor!$C$29 -> 616.32
A4: 3 | B4: LPG_CONS_EM | C4: 2023 | D4: June | E4: 0 | F4: 4.2 | G4: 19.2 | H4: 0 | I4: =G4*E4 -> 0 | J4: =I4*Emission_factor!$C$29 -> 0
A5: 4 | B5: LPG_CONS_EM | C5: 2023 | D5: July | E5: 0 | F5: 4.2 | G5: 19.2 | H5: 0 | I5: =G5*E5 -> 0 | J5: =I5*Emission_factor!$C$29 -> 0
A6: 5 | B6: LPG_CONS_EM | C6: 2023 | D6: August | E6: 0 | F6: 4.2 | G6: 19.2 | H6: 0 | I6: =G6*E6 -> 0 | J6: =I6*Emission_factor!$C$29 -> 0
A7: 6 | B7: LPG_CONS_EM | C7: 2023 | D7: September | E7: 4 | F7: 4.2 | G7: 19.2 | H7: 16.8 | I7: =G7*E7 -> 76.8 | J7: =I7*Emission_factor!$C$29 -> 410.88
A8: 7 | B8: LPG_CONS_EM | C8: 2023 | D8: October | E8: 5 | F8: 4.2 | G8: 19.2 | H8: 21 | I8: =G8*E8 -> 96 | J8: =I8*Emission_factor!$C$29 -> 513.6
A9: 8 | B9: LPG_CONS_EM | C9: 2023 | D9: November | E9: 3 | F9: 4.2 | G9: 19.2 | H9: 12.6 | I9: =G9*E9 -> 57.6 | J9: =I9*Emission_factor!$C$29 -> 308.16
A10: 9 | B10: LPG_CONS_EM | C10: 2023 | D10: December | E10: 3 | F10: 4.2 | G10: 19.2 | H10: 12.6 | I10: =G10*E10 -> 57.6 | J10: =I10*Emission_factor!$C$29 -> 308.16
A11: 10 | B11: LPG_CONS_EM | C11: 2024 | D11: January | E11: 4 | F11: 4.2 | G11: 19.2 | H11: 16.8 | I11: =G11*E11 -> 76.8 | J11: =I11*Emission_factor!$C$29 -> 410.88
A12: 11 | B12: LPG_CONS_EM | C12: 2024 | D12: February | E12: 3 | F12: 4.2 | G12: 19.2 | H12: 12.6 | I12: =G12*E12 -> 57.6 | J12: =I12*Emission_factor!$C$29 -> 308.16
A13: 12 | B13: LPG_CONS_EM | C13: 2024 | D13: March | E13: 1 | F13: 4.2 | G13: 19.2 | H13: 4.2 | I13: =G13*E13 -> 19.2 | J13: =I13*Emission_factor!$C$29 -> 102.72
E14: 29 | H14: 121.8 | I14: =SUM(I2:I13) -> 556.8 | J14: =I14*Emission_factor!$C$29 -> 2978.88
J15: KgCO2

Sheet FE_CHROM_PROD_EM
A1: Sl_no | B1: Process_code | C1: Year | D1: Month | E1: Ore | F1: Ferro_chrome | G1: Total_emisson
A2: 1 | B2: FE_CHROM_PROD_EM | C2: 2023 | D2: Apr | E2: 15074 | F2: =0.5*E2 -> 7537 | G2: =F2*Emission_factor!$C$30 -> 39946.1
A3: 2 | B3: FE_CHROM_PROD_EM | C3: 2023 | D3: May | E3: 23166 | F3: =0.5*E3 -> 11583 | G3: =F3*Emission_factor!$C$30 -> 61389.9
A4: 3 | B4: FE_CHROM_PROD_EM | C4: 2023 | D4: Jun | E4: 93456 | F4: =0.5*E4 -> 46728 | G4: =F4*Emission_factor!$C$30 -> 247658.4
A5: 4 | B5: FE_CHROM_PROD_EM | C5: 2023 | D5: Jul | E5: 9426 | F5: =0.5*E5 -> 4713 | G5: =F5*Emission_factor!$C$30 -> 24978.9
A6: 5 | B6: FE_CHROM_PROD_EM | C6: 2023 | D6: Aug | E6: 2498 | F6: =0.5*E6 -> 1249 | G6: =F6*Emission_factor!$C$30 -> 6619.7
A7: 6 | B7: FE_CHROM_PROD_EM | C7: 2023 | D7: Sep | E7: 0 | F7: =0.5*E7 -> 0 | G7: =F7*Emission_factor!$C$30 -> 0
A8: 7 | B8: FE_CHROM_PROD_EM | C8: 2023 | D8: Oct | E8: 3474 | F8: =0.5*E8 -> 1737 | G8: =F8*Emission_factor!$C$30 -> 9206.1
A9: 8 | B9: FE_CHROM_PROD_EM | C9: 2023 | D9: Nov | E9: 12636 | F9: =0.5*E9 -> 6318 | G9: =F9*Emission_factor!$C$30 -> 33485.4
A10: 9 | B10: FE_CHROM_PROD_EM | C10: 2023 | D10: Dec | E10: 22940 | F10: =0.5*E10 -> 11470 | G10: =F10*Emission_factor!$C$30 -> 60791
A11: 10 | B11: FE_CHROM_PROD_EM | C11: 2024 | D11: Jan | E11: 50748 | F11: =0.5*E11 -> 25374 | G11: =F11*Emission_factor!$C$30 -> 134482.2
A12: 11 | B12: FE_CHROM_PROD_EM | C12: 2024 | D12: Feb | E12: 60794 | F12: =0.5*E12 -> 30397 | G12: =F12*Emission_factor!$C$30 -> 161104.1
A13: 12 | B13: FE_CHROM_PROD_EM | C13: 2024 | D13: Mar | E13: 4948 | F13: =0.5*E13 -> 2474 | G13: =F13*Emission_factor!$C$30 -> 13112.2
D14: total | E14: =SUM(E2:E13) -> 299160 | F14: =0.5*E14 -> 149580 | G14: =F14*Emission_factor!$C$30 -> 792774
G15: kgCO2

Sheet STEEL_PROD_EM
A1: Sl_no | B1: Process_code | C1: Year | D1: Month | E1: Ore | F1: Steel | G1: Total_emissions
A2: 1 | B2: STEEL_PROD_EM | C2: 2023 | D2: Apr | E2: 15074 | F2: =0.5*E2 -> 7537 | G2: =F2*Emission_factor!$C$31 -> 19897.68
A3: 2 | B3: STEEL_PROD_EM | C3: 2023 | D3: May | E3: 23166 | F3: =0.5*E3 -> 11583 | G3: =F3*Emission_factor!$C$31 -> 30579.12
A4: 3 | B4: STEEL_PROD_EM | C4: 2023 | D4: Jun | E4: 93456 | F4: =0.5*E4 -> 46728 | G4: =F4*Emission_factor!$C$31 -> 123361.92
A5: 4 | B5: STEEL_PROD_EM | C5: 2023 | D5: Jul | E5: 9426 | F5: =0.5*E5 -> 4713 | G5: =F5*Emission_factor!$C$31 -> 12442.32
A6: 5 | B6: STEEL_PROD_EM | C6: 2023 | D6: Aug | E6: 2498 | F6: =0.5*E6 -> 1249 | G6: =F6*Emission_factor!$C$31 -> 3297.36
A7: 6 | B7: STEEL_PROD_EM | C7: 2023 | D7: Sep | E7: 0 | F7: =0.5*E7 -> 0 | G7: =F7*Emission_factor!$C$31 -> 0
A8: 7 | B8: STEEL_PROD_EM | C8: 2023 | D8: Oct | E8: 3474 | F8: =0.5*E8 -> 1737 | G8: =F8*Emission_factor!$C$31 -> 4585.68
A9: 8 | B9: STEEL_PROD_EM | C9: 2023 | D9: Nov | E9: 12636 | F9: =0.5*E9 -> 6318 | G9: =F9*Emission_factor!$C$31 -> 16679.52
A10: 9 | B10: STEEL_PROD_EM | C10: 2023 | D10: Dec | E10: 22940 | F10: =0.5*E10 -> 11470 | G10: =F10*Emission_factor!$C$31 -> 30280.8
A11: 10 | B11: STEEL_PROD_EM | C11: 2024 | D11: Jan | E11: 50748 | F11: =0.5*E11 -> 25374 | G11: =F11*Emission_factor!$C$31 -> 66987.36
A12: 11 | B12: STEEL_PROD_EM | C12: 2024 | D12: Feb | E12: 60794 | F12: =0.5*E12 -> 30397 | G12: =F12*Emission_factor!$C$31 -> 80248.08
A13: 12 | B13: STEEL_PROD_EM | C13: 2024 | D13: Mar | E13: 4948 | F13: =0.5*E13 -> 2474 | G13: =F13*Emission_factor!$C$31 -> 6531.36
D14: total | E14: =SUM(E2:E13) -> 299160 | F14: =0.5*E14 -> 149580 | G14: =F14*Emission_factor!$C$31 -> 394891.2
G15: kgCO2

Sheet WTP_ELECT_EM
A1: Sl_no | B1: Process_code | C1: Type | D1: Amount_WW (KLY) | E1: Energy/ m3 | F1: Total_energy (kWh) | G1: Total_emission
A2: 1 | B2: WTP_ELECT_EM | C2: ETP | D2: 530937 | E2: =(0.5+2)/2 -> 1.25 | F2: =E2*D2 -> 663671.25 | G2: =F2*Emission_factor!C32 -> 551411.92
G3: kgCO2

Sheet QC_CHEM_PROD_EM
A1: Sl_no | B1: Process_code | C1: Chemicals | D1: No_Samples | E1: Cons_Six_mnths | F1: Annual_Cons | G1: Unit | H1: m3 | I1: Annual_cons(kg) | J1: EF | K1: Total_emissions
A2: 1 | B2: QC_CHEM_PROD_EM | C2: NaOH PELLETS | D2: 435 | E2: 8.83 | G2: kg | I2: 17.66 | J2: 1.12 | K2: =J2*I2 -> 19.7792
A3: 2 | B3: QC_CHEM_PROD_EM | C3: CONC. H2SO4 | D3: 435 | E3: 13.622 | F3: 27.244 | G3: L | H3: 0.02744 | I3: =1.83*H3 -> 0.0502152 | J3: 0.14 | K3: =J3*I3 -> 0.007030128
A4: 3 | B4: QC_CHEM_PROD_EM | C4: NACL | D4: 435 | E4: 445 | F4: 890 | G4: g | I4: =F4/1000 -> 0.89 | J4: 0.2 | K4: =J4*I4 -> 0.178
A5: 4 | B5: QC_CHEM_PROD_EM | C5: HCL | D5: 435 | E5: 73.304 | F5: 146.608 | G5: L | H5: 0.146608 | I5: =1.19*H5 -> 0.17446352 | J5: 1.2 | K5: =J5*I5 -> 0.20935622
A6: 5 | B6: QC_CHEM_PROD_EM | C6: HF | D6: 435 | E6: 6.547 | F6: 13.094 | G6: L | H6: =F6/1000 -> 0.013094 | I6: =1.15*H6 -> 0.0150581 | J6: 2.82 | K6: =J6*I6 -> 0.042463842
A7: 6 | B7: QC_CHEM_PROD_EM | C7: SODIUM CARBONATE | D7: 435 | E7: 662 | F7: 1324 | G7: g | I7: =F7/1000 -> 1.324 | J7: 0.59 | K7: =J7*I7 -> 0.78116
A8: 7 | B8: QC_CHEM_PROD_EM | C8: NH4CL SALT | D8: 435 | E8: 6.557 | F8: 13.114 | G8: kg | I8: 13.114 | J8: 1.18 | K8: =J8*I8 -> 15.47452
A9: 8 | B9: QC_CHEM_PROD_EM | C9: AMMONIA SOLUTION | D9: 435 | E9: 39.2 | F9: 78.4 | G9: L | H9: =F9/1000 -> 0.0784 | I9: =0.9*H9 -> 0.07056 | J9: 2.6 | K9: =J9*I9 -> 0.183456
A10: 9 | B10: QC_CHEM_PROD_EM | C10: POTASSIUM HYDROXIDE | D10: 435 | E10: 5.96 | F10: 11.92 | G10: kg | I10: 11.92 | J10: 0.77 | K10: =J10*I10 -> 9.1784
A11: 10 | B11: QC_CHEM_PROD_EM | C11: ETHANOL | D11: 435 | E11: 3060 | F11: 6.12 | G11: L | H11: =F11/1000 -> 0.00612 | I11: =789 *H11 -> 4.82868 | J11: 1.24 | K11: =J11*I11 -> 5.9875632
A12: 11 | B12: QC_CHEM_PROD_EM | C12: AMMONIA CHLORIDE | D12: 435 | E12: 1356 | F12: 2712 | G12: g | I12: =F12/1000 -> 2.712 | J12: 1.2 | K12: =J12*I12 -> 3.2544
A13: 12 | B13: QC_CHEM_PROD_EM | C13: NITRIC ACID | D13: 435 | E13: 4.365 | F13: 8.73 | G13: L | H13: =F13/1000 -> 0.00873 | I13: =1.51*H13 -> 0.0131823 | J13: 3.18 | K13: =J13*I13 -> 0.041919714
G14: Mean | J14: =AVERAGE(J2:J13) -> 1.3533333 | K14: =SUM(K2:K13) -> 55.117469
K15: kgCO2

Sheet CHEM_ETP_PROD_EM
A1: Sl_no | B1: Process_code | C1: Chemicals | D1: Consumption (kg) | E1: Total_emission
B2: CHEM_ETP_PROD_EM | C2: Ferrous Sulphate | D2: 38425 | E2: =D2*Emission_factor!C35 -> 12611.085
B3: CHEM_ETP_PROD_EM | C3: NaOH | D3: 1350 | E3: =D3*Emission_factor!C36 -> 1512
B4: CHEM_ETP_PROD_EM | C4: Cationic Polyelectrolyte | D4: 655 | E4: 0
E5: =SUM(E2:E4) -> 14123.085
E6: kgCO2

Sheet DISP_TYRE_EM
A1: Sl_no | B1: Process_code | C1: Type | D1: No | E1: Weight | F1: Total_wt | G1: Total_emissions
A2: 1 | B2: DISP_TYRE_EM | C2: HEMV | D2: 511 | E2: 62 | F2: =31682/1000 -> 31.682 | G2: =F2*Emission_factor!C37 -> 3168.2
A3: 2 | B3: DISP_TYRE_EM | C3: LMV
G4: =SUM(G2:G3) -> 3168.2
G5: kgCO2

Sheet DISP_LUBE_EM
A1: Sl NO | B1: Process_code | C1: Type | D1: Sub_process | E1: Annual_cons | F1: Total_emissions
A2: 1 | B2: DISP_LUBE_EM | C2: Engine_oil | D2: Drilling | E2: 1800 | F2: =E2*Emission_factor!$C$38 -> 4752
A3: 2 | B3: DISP_LUBE_EM | C3: Gear Oil | D3: Drilling | E3: 900 | F3: =E3*Emission_factor!$C$38 -> 2376
A4: 3 | B4: DISP_LUBE_EM | C4: Engine_oil | D4: Vehicle | E4: 50947 | F4: =E4*Emission_factor!$C$38 -> 134500.08
A5: 4 | B5: DISP_LUBE_EM | C5: Gear Oil | D5: Vehicle | E5: 3968 | F5: =E5*Emission_factor!$C$38 -> 10475.52
C6: Total | E6: 57615 | F6: =E6*Emission_factor!$C$38 -> 152103.6
F7: KgCO2

Sheet TRANS_2WHS_EM
A1: Sl_no | B1: Process_code | C1: No | D1: Distance (km)
A2: 1 | B2: TRANS_2WHS_EM | C2: 20209 | D2: 2 | E2: 5 | F2: 10 | G2: 20
C3: Total_emissions | D3: =($C$2/4)*Emission_factor!$C$41*(D2) -> 343.72141 | E3: =($C$2/4)*Emission_factor!$C$41*(E2) -> 859.30352 | F3: =($C$2/4)*Emission_factor!$C$41*(F2) -> 1718.607 | G3: =($C$2/4)*Emission_factor!$C$41*(G2) -> 3437.2141 | H3: =SUM(D3:G3) -> 6358.8461
C4: kgCO2

Sheet TRANS_BUS_EM
A1: Sl_no | B1: Process_code | C1: No | D1: HSD (lts) | E1: Distance | F1: Mileage | G1: Total_emission(fuel) | H1: Total_emission (dist)
A2: 1 | B2: TRANS_BUS_EM | C2: 1 | D2: =E2/F2 -> 5646 | E2: 33876 | F2: 6 | G2: =D2*Emission_factor!C7 -> 15062.963 | H2: =E2*Emission_factor!C44*30 -> 15406.805 | I2: Assumption
G3: kgCO2 | H3: kgCO2

Sheet TRANS_PLANE_EM
A1: Sl No | B1: Process_code | C1: Date | D1: Place | E1: Pax | F1: Distance | G1: Total_emissions
A2: 1 | B2: TRANS_PLANE_EM | C2: 27-5-23 To 3-6-23 | D2: DELHI | E2: 1 | F2: =1813*2 -> 3626 | G2: =F2*E2*Emission_factor!$C$45 -> 438.746
A3: 2 | B3: TRANS_PLANE_EM | C3: 03-1-24 TO 8-1-24 | D3: NAGPUR | E3: 1 | F3: =2*1562 -> 3124 | G3: =F3*E3*Emission_factor!$C$45 -> 378.004
A4: 3 | B4: TRANS_PLANE_EM | C4: 03-1-24 TO 8-1-24 | D4: NAGPUR | E4: 1 | F4: =2*1562 -> 3124 | G4: =F4*E4*Emission_factor!$C$45 -> 378.004
A5: 4 | B5: TRANS_PLANE_EM | C5: 03-1-24 TO 8-1-24 | D5: NAGPUR | E5: 1 | F5: =2*1562 -> 3124 | G5: =F5*E5*Emission_factor!$C$45 -> 378.004
F6: Total | G6: =SUM(G2:G5) -> 1572.758
G7: kgCO2

Sheet TRANS_LMV_EM
A1: Sl_no | B1: Process | C1: Date | D1: Place | E1: Pax | F1: Distance | G1: Tot_dist | H1: Total_emission
A2: 1 | B2: TRANS_LMV_EM | C2: 45203 | D2: DDM OFFICE, JAJPUR | E2: 1 | F2: 84 | G2: =2*F2 -> 168 | H2: =Emission_factor!$C$43*TRANS_LMV_EM!G2 -> 29.876727
A3: 2 | B3: TRANS_LMV_EM | C3: 24-4-23 TO 25-4-23 | D3: RTO, BBSR | E3: 1 | F3: 121 | G3: =2*F3 -> 242 | H3: =Emission_factor!$C$43*TRANS_LMV_EM!G3 -> 43.036714
A4: 3 | B4: TRANS_LMV_EM | C4: 24-4-23 TO 25-4-23 | D4: RTO, BBSR | E4: 1 | F4: 121 | G4: =2*F4 -> 242 | H4: =Emission_factor!$C$43*TRANS_LMV_EM!G4 -> 43.036714
A5: 4 | B5: TRANS_LMV_EM | C5: 45082 | D5: DDM OFFICE, JAJPUR | E5: 1 | F5: 84 | G5: =2*F5 -> 168 | H5: =Emission_factor!$C$43*TRANS_LMV_EM!G5 -> 29.876727
A6: 5 | B6: TRANS_LMV_EM | C6: 45235 | D6: DDM OFFICE, JAJPUR | E6: 1 | F6: 84 | G6: =2*F6 -> 168 | H6: =Emission_factor!$C$43*TRANS_LMV_EM!G6 -> 29.876727
A7: 6 | B7: TRANS_LMV_EM | C7: 24-5-23 TO 30-5-23 | D7: RO,JK-ROAD | E7: 1 | F7: 121 | G7: =2*F7 -> 242 | H7: =Emission_factor!$C$43*TRANS_LMV_EM!G7 -> 43.036714
A8: 7 | B8: TRANS_LMV_EM | C8: 45052 | D8: DDM OFFICE, JAJPUR | E8: 1 | F8: 84 | G8: =2*F8 -> 168 | H8: =Emission_factor!$C$43*TRANS_LMV_EM!G8 -> 29.876727
A9: 8 | B9: TRANS_LMV_EM | C9: 45266 | D9: DDM OFFICE, JAJPUR | E9: 1 | F9: 84 | G9: =2*F9 -> 168 | H9: =Emission_factor!$C$43*TRANS_LMV_EM!G9 -> 29.876727
A10: 9 | B10: TRANS_LMV_EM | C10: 6/23/2023 | D10: DDM OFFICE, JAJPUR | E10: 1 | F10: 84 | G10: =2*F10 -> 168 | H10: =Emission_factor!$C$43*TRANS_LMV_EM!G10 -> 29.876727
A11: 10 | B11: TRANS_LMV_EM | C11: 6/27/2023 | D11: IDCOL,BHUBANESWAR | E11: 1 | F11: 121 | G11: =2*F11 -> 242 | H11: =Emission_factor!$C$43*TRANS_LMV_EM!G11 -> 43.036714
A12: 11 | B12: TRANS_LMV_EM | C12: 10-7-24 TO 15-7-23 | D12: GANDHAMARDAN MINES, KEONJHAR | E12: 1 | F12: 123 | G12: =2*F12 -> 246 | H12: =Emission_factor!$C$43*TRANS_LMV_EM!G12 -> 43.748065
A13: 12 | B13: TRANS_LMV_EM | C13: 7/27/2023 | D13: IBM OFFICE, BHUBANESWAR | E13: 1 | F13: 121 | G13: =2*F13 -> 242 | H13: =Emission_factor!$C$43*TRANS_LMV_EM!G13 -> 43.036714
A14: 13 | B14: TRANS_LMV_EM | C14: 45115 | D14: DDM OFFICE, JAJPUR | E14: 1 | F14: 84 | G14: =2*F14 -> 168 | H14: =Emission_factor!$C$43*TRANS_LMV_EM!G14 -> 29.876727
A15: 14 | B15: TRANS_LMV_EM | C15: 21-08-2023 TO 24-8-23 | D15: KODINGAMALI MINES | E15: 1 | F15: 541 | G15: =2*F15 -> 1082 | H15: =Emission_factor!$C$43*TRANS_LMV_EM!G15 -> 192.42035
A16: 15 | B16: TRANS_LMV_EM | C16: 09-9-23 TO 10-9-23 | D16: SILICON COLLGE, BHUBANESWAR | E16: 1 | F16: 121 | G16: =2*F16 -> 242 | H16: =Emission_factor!$C$43*TRANS_LMV_EM!G16 -> 43.036714
A17: 16 | B17: TRANS_LMV_EM | C17: 25-9-23 TO 28-9-23 | D17: HO, BHUBANESWAR | E17: 1 | F17: 121 | G17: =2*F17 -> 242 | H17: =Emission_factor!$C$43*TRANS_LMV_EM!G17 -> 43.036714
A18: 17 | B18: TRANS_LMV_EM | C18: 10/27/2023 | D18: DDM OFFICE, JAJPUR | E18: 1 | F18: 84 | G18: =2*F18 -> 168 | H18: =Emission_factor!$C$43*TRANS_LMV_EM!G18 -> 29.876727
A19: 18 | B19: TRANS_LMV_EM | C19: 45088 | D19: DDM OFFICE, JAJPUR | E19: 1 | F19: 84 | G19: =2*F19 -> 168 | H19: =Emission_factor!$C$43*TRANS_LMV_EM!G19 -> 29.876727
H20: =SUM(H2:H19) -> 806.31596
H21: kgCO2

Sheet TRANS_6WHS_EM
A1: Sl_no | B1: Process_code | C1: Type | D1: Month | E1: Year | F1: Client | G1: Place | H1: No | I1: Distance | J1: Total Distance | K1: Total_Emission
A2: 1 | B2: TRANS_6WHS_EM | C2: 6WHEELER | D2: April | E2: 2023 | F2: Orissa Chrome Export and Mining Co. Ltd. | G2: BHUBANESWAR | H2: 16 | I2: 30 | J2: =H2*I2*2 -> 960 | K2: =J2*Emission_factor!$C$48 -> 569.088
A3: 2 | B3: TRANS_6WHS_EM | C3: 6WHEELER | D3: April | E3: 2023 | F3: Anand Exports | G3: GOLAGAON | H3: 342 | I3: 51 | J3: =H3*I3*2 -> 34884 | K3: =J3*Emission_factor!$C$48 -> 20679.235
A4: 3 | B4: TRANS_6WHS_EM | C4: 6WHEELER | D4: April | E4: 2023 | F4: MISRILALL MINES PVT. LTD. | G4: PANKAPAL | H4: 8 | I4: 47 | J4: =H4*I4*2 -> 752 | K4: =J4*Emission_factor!$C$48 -> 445.7856
A5: 4 | B5: TRANS_6WHS_EM | C5: 6WHEELER | D5: April | E5: 2023 | F5: Visa Steel Ltd | G5: JAKHAPURA | H5: 91 | I5: 51 | J5: =H5*I5*2 -> 9282 | K5: =J5*Emission_factor!$C$48 -> 5502.3696
A6: 5 | B6: TRANS_6WHS_EM | C6: 6WHEELER | D6: May | E6: 2023 | F6: Anand Exports | G6: GOLAGAON | H6: 79 | I6: 51 | J6: =H6*I6*2 -> 8058 | K6: =J6*Emission_factor!$C$48 -> 4776.7824
A7: 6 | B7: TRANS_6WHS_EM | C7: 6WHEELER | D7: May | E7: 2023 | F7: JINDAL STAINLESS LIMITED | G7: DANAGADI | H7: 45 | I7: 47.1 | J7: =H7*I7*2 -> 4239 | K7: =J7*Emission_factor!$C$48 -> 2512.8792
A8: 7 | B8: TRANS_6WHS_EM | C8: 6WHEELER | D8: May | E8: 2023 | F8: PRIME INDUSTRIES | G8: RAHANJA | H8: 42 | I8: 113 | J8: =H8*I8*2 -> 9492 | K8: =J8*Emission_factor!$C$48 -> 5626.8576
A9: 8 | B9: TRANS_6WHS_EM | C9: 6WHEELER | D9: May | E9: 2023 | F9: Anand Exports | G9: GOLAGAON | H9: 69 | I9: 51 | J9: =H9*I9*2 -> 7038 | K9: =J9*Emission_factor!$C$48 -> 4172.1264
A10: 9 | B10: TRANS_6WHS_EM | C10: 6WHEELER | D10: May | E10: 2023 | F10: JINDAL STAINLESS LIMITED | G10: DANAGADI | H10: 46 | I10: 47.1 | J10: =H10*I10*2 -> 4333.2 | K10: =J10*Emission_factor!$C$48 -> 2568.721
A11: 10 | B11: TRANS_6WHS_EM | C11: 6WHEELER | D11: May | E11: 2023 | F11: Balasore Alloys Ltd | G11: BALASORE | H11: 25 | I11: 168 | J11: =H11*I11*2 -> 8400 | K11: =J11*Emission_factor!$C$48 -> 4979.52
A12: 11 | B12: TRANS_6WHS_EM | C12: 6WHEELER | D12: May | E12: 2023 | F12: Visa Steel Ltd | G12: JAKHAPURA | H12: 33 | I12: 51 | J12: =H12*I12*2 -> 3366 | K12: =J12*Emission_factor!$C$48 -> 1995.3648
A13: 12 | B13: TRANS_6WHS_EM | C13: 6WHEELER | D13: May | E13: 2023 | F13: Visa Steel Ltd | G13: JAKHAPURA | H13: 16 | I13: 51 | J13: =H13*I13*2 -> 1632 | K13: =J13*Emission_factor!$C$48 -> 967.4496
... A542: 541 | B542: TRANS_6WHS_EM | C542: 6WHEELER | D542: Mar | E542: 2024 | F542: SUBHALAXMI MINERALS | G542: SOLEI JAJPUR | H542: 8 | I542: 55.7 | J542: =H542*I542*2 -> 891.2 | K542: =J542*Emission_factor!$C$48 -> 528.30336
I543: Total | J543: =SUM(J2:J542) -> 2493244.8 | K543: =J543*Emission_factor!$C$48 -> 1477995.5
J544: km | K544: kgCO2

Sheet TRANS_12-14WHS_EM
A1: Sl_no | B1: Process_code | C1: Client | D1: Place | E1: Type | F1: No | G1: Distance | H1: Month | I1: Year | J1: Total_dist | K1: Total_emission
A2: 1 | B2: TRANS_12_14WHS_EM | C2: JAI BALAJI INDUSTRIES LTD. UNIT-IV | D2: DURGAPUR | E2: 14/12WHEELER | F2: 10 | G2: 417 | H2: May | I2: 2023 | J2: =G2*F2*2 -> 8340 | K2: =J2*Emission_factor!$C$49 -> 6150.75
A3: 2 | B3: TRANS_12_14WHS_EM | C3: Shyam Metalics and Energy Ltd | D3: SAMBALPUR | E3: 14/12WHEELER | F3: 23 | G3: 251 | H3: June | I3: 2023 | J3: =G3*F3*2 -> 11546 | K3: =J3*Emission_factor!$C$49 -> 8515.175
A4: 3 | B4: TRANS_12_14WHS_EM | C4: JAI BALAJI INDUSTRIES LTD. UNIT-IV | D4: DURGAPUR | E4: 14/12WHEELER | F4: 14 | G4: 438 | H4: June | I4: 2023 | J4: =G4*F4*2 -> 12264 | K4: =J4*Emission_factor!$C$49 -> 9044.7
A5: 4 | B5: TRANS_12_14WHS_EM | C5: Shyam Metalics and Energy Ltd | D5: SAMBALPUR | E5: 14/12WHEELER | F5: 2 | G5: 251 | H5: June | I5: 2023 | J5: =G5*F5*2 -> 1004 | K5: =J5*Emission_factor!$C$49 -> 740.45
A6: 5 | B6: TRANS_12_14WHS_EM | C6: JAI BALAJI INDUSTRIES LTD. UNIT-IV | D6: DURGAPUR | E6: 14/12WHEELER | F6: 22 | G6: 438 | H6: June | I6: 2023 | J6: =G6*F6*2 -> 19272 | K6: =J6*Emission_factor!$C$49 -> 14213.1
A7: 6 | B7: TRANS_12_14WHS_EM | C7: JAI BALAJI INDUSTRIES LTD. UNIT-IV | D7: DURGAPUR | E7: 14/12WHEELER | F7: 1 | G7: 438 | H7: June | I7: 2023 | J7: =G7*F7*2 -> 876 | K7: =J7*Emission_factor!$C$49 -> 646.05
A8: 7 | B8: TRANS_12_14WHS_EM | C8: JAI BALAJI INDUSTRIES LTD. UNIT-IV | D8: DURGAPUR | E8: 14/12WHEELER | F8: 31 | G8: 438 | H8: June | I8: 2023 | J8: =G8*F8*2 -> 27156 | K8: =J8*Emission_factor!$C$49 -> 20027.55
A9: 8 | B9: TRANS_12_14WHS_EM | C9: JAI BALAJI INDUSTRIES LTD. UNIT-IV | D9: DURGAPUR | E9: 14/12WHEELER | F9: 37 | G9: 438 | H9: June | I9: 2023 | J9: =G9*F9*2 -> 32412 | K9: =J9*Emission_factor!$C$49 -> 23903.85
A10: 9 | B10: TRANS_12_14WHS_EM | C10: Shyam Metalics and Energy Ltd | D10: SAMBALPUR | E10: 14/12WHEELER | F10: 15 | G10: 251 | H10: June | I10: 2023 | J10: =G10*F10*2 -> 7530 | K10: =J10*Emission_factor!$C$49 -> 5553.375
A11: 10 | B11: TRANS_12_14WHS_EM | C11: JAI BALAJI INDUSTRIES LTD. UNIT-IV | D11: DURGAPUR | E11: 14/12WHEELER | F11: 4 | G11: 438 | H11: June | I11: 2023 | J11: =G11*F11*2 -> 3504 | K11: =J11*Emission_factor!$C$49 -> 2584.2
A12: 11 | B12: TRANS_12_14WHS_EM | C12: Shyam Metalics and Energy Ltd | D12: SAMBALPUR | E12: 14/12WHEELER | F12: 2 | G12: 251 | H12: June | I12: 2023 | J12: =G12*F12*2 -> 1004 | K12: =J12*Emission_factor!$C$49 -> 740.45
A13: 12 | B13: TRANS_12_14WHS_EM | C13: JAI BALAJI INDUSTRIES LTD. UNIT-IV | D13: DURGAPUR | E13: 14/12WHEELER | F13: 10 | G13: 438 | H13: July | I13: 2023 | J13: =G13*F13*2 -> 8760 | K13: =J13*Emission_factor!$C$49 -> 6460.5
... A122: 121 | B122: TRANS_12_14WHS_EM | C122: SURYA ALLOY INDUSTRIES LIMITED | D122: DURGAPUR | E122: 14/12WHEELER | F122: 16 | G122: 438 | H122: Mar | I122: 2024 | J122: =G122*F122*2 -> 14016 | K122: =J122*Emission_factor!$C$49 -> 10336.8
I123: Total | J123: =SUM(J2:J122) -> 1553002 | K123: =J123*Emission_factor!$C$49 -> 1145339
J124: Km

Sheet MIN_QC_TRANS_EM
A1: Sl no | B1: Process_code | C1: Type | D1: Total_distance | E1: Total_emission
A2: 1 | B2: MIN_QC_TRANS_EM | C2: Bolero Camper (LMV) | D2: 126942 | E2: =D2*Emission_factor!C43 -> 22575.069
E3: kgCO2

Sheet CORE_QC_TRANS_EM
A1: Sl no | B1: Process_code | C1: Type | D1: Total_distance | E1: Total_emissions
A2: 1 | B2: CORE_QC_TRANS_EM | C2: Bolero Camper (LMV) | D2: 253884 | E2: =D2*Emission_factor!C42 -> 45149.038
E3: kgCO2

Sheet CORE_TRANS_BB_EM
A1: Sl no | B1: Process_code | C1: Type | D1: Total_distance | E1: Total_emission
A2: 1 | B2: CORE_TRANS_BB_EM | C2: Bus | D2: 115200 | E2: =D2*Emission_factor!C43 -> 20486.899
E3: kgCO2

Sheet GEN_ITEM_PROD_EM
A1: Sl_no | B1: Process_code | C1: Item | D1: Consumption | F1: Wt (kg) | G1: EF | H1: unit | I1: Total_emission
A2: 1 | B2: GEN_ITEM_PROD_EM | C2: LOADING SLIP | D2: 270 | F2: =(6.75*D2)/1000 -> 1.8225 | G2: 2.42 | H2: kg CO2 /kg | I2: =F2*G2 -> 4.41045
A3: 2 | B3: GEN_ITEM_PROD_EM | C3: ENVOLPE (MID) | D3: 200 | F3: =(50*D3)/1000 -> 10 | G3: 2.42 | I3: =F3*G3 -> 24.2
A4: 3 | B4: GEN_ITEM_PROD_EM | C4: ENVLOPE ( BIG) | D4: 195 | F4: =(100*D4)/1000 -> 19.5 | G4: 2.42 | I4: =F4*G4 -> 47.19
A5: 4 | B5: GEN_ITEM_PROD_EM | C5: A4 SIZE PAPER | D5: 134 | F5: =2.27*D5 -> 304.18 | G5: 2.42 | I5: =F5*G5 -> 736.1156
A6: 5 | B6: GEN_ITEM_PROD_EM | C6: ENVOLPE (SMALL) | D6: 130 | F6: =(6.75*D6)/1000 -> 0.8775 | G6: 2.42 | I6: =F6*G6 -> 2.12355
A7: 6 | B7: GEN_ITEM_PROD_EM | C7: L. B SOAP | D7: 111 | F7: =(100/1000)*D7 -> 11.1 | G7: 0.00771 | H7: kg CO2 /kg | I7: =F7*G7 -> 0.085581
A8: 7 | B8: GEN_ITEM_PROD_EM | C8: PAPER STRAW | D8: 100 | G8: 1.38 | H8: gCO2/straw | I8: =(G8*D8)/1000 -> 0.138
A9: 8 | B9: GEN_ITEM_PROD_EM | C9: BANDAGE | D9: 96 | E9: Pkt | G9: 95.95 | H9: gCO2/bandages
A10: 9 | B10: GEN_ITEM_PROD_EM | C10: PHENYLE ( WHITE) | D10: 92 | F10: =D10*1 -> 92 | G10: 3.87 | H10: kgCO2/kg | I10: =G10*F10 -> 356.04
A11: 10 | B11: GEN_ITEM_PROD_EM | C11: FLY LEAF | D11: 79
A12: 11 | B12: GEN_ITEM_PROD_EM | C12: ENVLOPE CLOTH | D12: 72
A13: 12 | B13: GEN_ITEM_PROD_EM | C13: LIME | D13: 70
A14: 13 | B14: GEN_ITEM_PROD_EM | C14: PENCIL BATTERY | D14: 66 | G14: 0.107 | H14: kg COe2/batt | I14: =G14*D14 -> 7.062
A15: 14 | B15: GEN_ITEM_PROD_EM | C15: 9WT LED LAMP | D15: 58
A16: 15 | B16: GEN_ITEM_PROD_EM | C16: SURF 500G | D16: 55 | F16: =0.5*D16 -> 27.5 | G16: 1.7 | H16: kgCO2/kg | I16: =F16*G16 -> 46.75
A17: 16 | B17: GEN_ITEM_PROD_EM | C17: ODONIL | D17: 52 | E17: Pkt
